<?xml version="1.0" ?>
<!-- =================================================================================== -->
<!-- |    This document was autogenerated by xacro from reflex.urdf.xacro              | -->
<!-- |    EDITING THIS FILE BY HAND IS NOT RECOMMENDED                                 | -->
<!-- =================================================================================== -->
<robot name="reflex">
  <!-- ===================================== MATERIALS ======================================= -->
  <!-- Gazebo won't be able to read these colors but they are required RViz 
  see this issue https://robotics.stackexchange.com/questions/20506/gazebo-not-reading-the-material-color-in-urdf -->
  <material name="black">
    <color rgba="0 0 0 0"/>
  </material>
  <material name="dark_grey">
    <color rgba="0.2 0.2 0.2 1"/>
  </material>
  <material name="gold">
    <color rgba="0.996078431372549 0.8470588235294118 0.36470588235294116 1"/>
  </material>
  <!-- ======================================= Masses ======================================== -->
  <!-- These are rough approximations, the total hand mass was measured to be about 0.9kg     -->
  <!-- final mass: 0.6+0.03+2*0.02+3*(0.025+0.015+0.02+0.02+0.01) = 0.94 -->
  <!-- ====================================== Link Macros ==================================== -->
  <!-- =================================== Tactile macros =================================== -->
  <!-- Sensor links are rendered only to give a link that the Gazebo sensor plugin can latch  -->
  <!-- onto. As such, the collision and inertia are bogus and the visual is defines an        -->
  <!-- approximation of the sensor size. It's important that the mass and inertia are low     -->
  <!-- enough not to interfere with the hand dynamics, but not so small that they physics     -->
  <!-- engine chokes on it (e.g. 1e-8 is too small and the links disappear).                  -->
  <!-- ===================================== Joint Macros ===================================== -->
  <!-- REVOLUTE JOINTS -->
  <!-- =============================================================================== -->
  <!-- The preceding macros are used here to actually construct the kinematic structure-->
  <link name="shell">
    <visual>
      <origin rpy="0 0 0" xyz="0 0 0"/>
      <geometry>
        <mesh filename="/home/parallels/catkin_ws/src/grasp_refinement/reflex_stack/reflex_simulator/description/meshes/reflex/base_link.stl"/>
      </geometry>
      <material name="black"/>
    </visual>
    <inertial>
      <origin rpy="0 0 0" xyz="0.01 0 0.035"/>
      <mass value="0.6"/>
      <inertia ixx="0.0005978" ixy="0.0" ixz="0.0" iyy="0.00109" iyz="0.0" izz="0.0011978"/>
    </inertial>
    <collision>
      <origin rpy="0 0 0" xyz="0 0 0"/>
      <geometry>
        <mesh filename="/home/parallels/catkin_ws/src/grasp_refinement/reflex_stack/reflex_simulator/description/meshes/reflex/base_link_coll.stl"/>
      </geometry>
    </collision>
  </link>
  <link name="pad">
    <visual>
      <origin rpy="0 0 0" xyz="0 0 0"/>
      <geometry>
        <mesh filename="/home/parallels/catkin_ws/src/grasp_refinement/reflex_stack/reflex_simulator/description/meshes/reflex/pad.stl"/>
      </geometry>
      <material name="dark_grey"/>
    </visual>
    <inertial>
      <origin rpy="0 0 0" xyz="0 0.011 0.005"/>
      <mass value="0.03"/>
      <inertia ixx="4.3459999999999994e-05" ixy="0.0" ixz="0.0" iyy="5.989e-05" iyz="0.0" izz="1.8849999999999997e-05"/>
    </inertial>
    <collision>
      <origin rpy="0 0 0" xyz="0 0 0"/>
      <geometry>
        <mesh filename="/home/parallels/catkin_ws/src/grasp_refinement/reflex_stack/reflex_simulator/description/meshes/reflex/pad_coll.stl"/>
      </geometry>
    </collision>
  </link>
  <joint name="shell_to_pad" type="fixed">
    <origin rpy="1.570796326795 0 -1.570796326795" xyz="0.02 0 0.063"/>
    <parent link="shell"/>
    <child link="pad"/>
    <axis xyz="0 0 0"/>
  </joint>
  <joint name="preshape_1" type="revolute">
    <parent link="shell"/>
    <child link="swivel_1"/>
    <dynamics damping="0.1" friction="0.0"/>
    <limit effort="2" lower="0.0" upper="1.570796326795" velocity="0.5"/>
    <origin rpy="0 0 0" xyz="0.0503973683071414 -0.026 0.063"/>
    <axis xyz="0 0 -1"/>
  </joint>
  <link name="swivel_1">
    <visual>
      <origin rpy="0 0 0" xyz="0 0 0"/>
      <geometry>
        <mesh filename="/home/parallels/catkin_ws/src/grasp_refinement/reflex_stack/reflex_simulator/description/meshes/reflex/swivel_1.stl"/>
      </geometry>
      <material name="black"/>
    </visual>
    <inertial>
      <origin rpy="0 0 0" xyz="0 0 0.0075"/>
      <mass value="0.02"/>
      <inertia ixx="1.8749999999999998e-06" ixy="0.0" ixz="0.0" iyy="1.8749999999999998e-06" iyz="0.0" izz="2.9999999999999997e-06"/>
    </inertial>
    <collision>
      <origin rpy="0 0 0" xyz="0 0 0"/>
      <geometry>
        <mesh filename="/home/parallels/catkin_ws/src/grasp_refinement/reflex_stack/reflex_simulator/description/meshes/reflex/swivel_1_coll.stl"/>
      </geometry>
    </collision>
  </link>
  <joint name="proximal_joint_1" type="revolute">
    <child link="proximal_1"/>
    <axis xyz="0 -1 0"/>
    <dynamics damping="0.1" friction="0.0"/>
    <limit effort="2" lower="0.0" upper="3.14159265359" velocity="0.5"/>
    <origin rpy="0 0.28 0" xyz="0.01 0 0.0186"/>
    <parent link="swivel_1"/>
  </joint>
  <link name="proximal_1">
    <visual>
      <origin rpy="3.14159265359 0 0" xyz="-0.011 0.007 0.011"/>
      <geometry>
        <mesh filename="/home/parallels/catkin_ws/src/grasp_refinement/reflex_stack/reflex_simulator/description/meshes/reflex/proximal.stl"/>
      </geometry>
      <material name="black"/>
    </visual>
    <inertial>
      <origin rpy="0 0 0" xyz="0.024499999999999997 0 0"/>
      <mass value="0.025"/>
      <inertia ixx="7.083333333333334e-07" ixy="0.0" ixz="0.0" iyy="1.0802083333333333e-05" iyz="0.0" izz="1.0910416666666665e-05"/>
    </inertial>
    <collision>
      <origin rpy="3.14159265359 0 0" xyz="-0.011 0.007 0.011"/>
      <geometry>
        <mesh filename="/home/parallels/catkin_ws/src/grasp_refinement/reflex_stack/reflex_simulator/description/meshes/reflex/proximal_coll.stl"/>
      </geometry>
    </collision>
  </link>
  <joint name="proximal_1_to_pad" type="fixed">
    <origin rpy="1.570796326795 0 -1.570796326795" xyz="0 0 0"/>
    <parent link="proximal_1"/>
    <child link="proximal_1_pad"/>
  </joint>
  <link name="proximal_1_pad">
    <visual>
      <origin rpy="1.570796326795 1.570796326795 0" xyz="-0.008 0.014 -0.002"/>
      <geometry>
        <mesh filename="/home/parallels/catkin_ws/src/grasp_refinement/reflex_stack/reflex_simulator/description/meshes/reflex/proximal_pad.stl"/>
      </geometry>
      <material name="dark_grey"/>
    </visual>
    <inertial>
      <origin rpy="0 0 0" xyz="0 0.004 -0.036"/>
      <mass value="0.015"/>
      <inertia ixx="3.879999999999999e-06" ixy="0.0" ixz="0.0" iyy="3.6999999999999993e-06" iyz="0.0" izz="8.199999999999999e-07"/>
    </inertial>
    <collision>
      <origin rpy="1.570796326795 1.570796326795 0" xyz="-0.008 0.014 -0.002"/>
      <geometry>
        <mesh filename="/home/parallels/catkin_ws/src/grasp_refinement/reflex_stack/reflex_simulator/description/meshes/reflex/proximal_pad_coll.stl"/>
      </geometry>
    </collision>
  </link>
  <joint name="proximal_1_to_flex" type="revolute">
    <origin rpy="0 0 0" xyz="0.06199999999999999 0 -0.002"/>
    <parent link="proximal_1"/>
    <child link="finger_1_flex_link"/>
    <axis xyz="0 -1 0"/>
    <dynamics damping="0.05" friction="0.0"/>
    <limit effort="1.0" lower="0.0" upper="0.5235987755983333" velocity="0.25"/>
  </joint>
  <link name="finger_1_flex_link">
    <visual>
      <origin rpy="0 0 0" xyz="0.0085 0 0.00325"/>
      <geometry>
        <box size="0.017 0.014 0.0065"/>
      </geometry>
      <material name="gold"/>
    </visual>
    <inertial>
      <origin rpy="0 0 0" xyz="0.0085 0 0.00325"/>
      <mass value="0.02"/>
      <inertia ixx="3.970833333333333e-07" ixy="0.0" ixz="0.0" iyy="5.520833333333334e-07" iyz="0.0" izz="8.083333333333335e-07"/>
    </inertial>
    <collision>
      <origin rpy="0 0 0" xyz="0.0085 0 0.00325"/>
      <geometry>
        <box size="0.017 0.014 0.0065"/>
      </geometry>
    </collision>
  </link>
  <joint name="flex_to_distal_1" type="revolute">
    <origin rpy="0 0 0" xyz="0.017 0 0"/>
    <parent link="finger_1_flex_link"/>
    <child link="distal_1"/>
    <axis xyz="0 -1 0"/>
    <dynamics damping="0.05" friction="0.0"/>
    <limit effort="1.0" lower="0.0" upper="0.5235987755983333" velocity="0.25"/>
  </joint>
  <link name="distal_1">
    <visual>
      <origin rpy="3.14159265359 0 0" xyz="-0.08549999999999999 0.007 0.01225"/>
      <geometry>
        <mesh filename="/home/parallels/catkin_ws/src/grasp_refinement/reflex_stack/reflex_simulator/description/meshes/reflex/distal.stl"/>
      </geometry>
      <material name="black"/>
    </visual>
    <inertial>
      <origin rpy="0 0 0" xyz="0.018 0 0.004"/>
      <mass value="0.02"/>
      <inertia ixx="5.666666666666667e-07" ixy="0.0" ixz="0.0" iyy="2.3999999999999995e-06" iyz="0.0" izz="2.4866666666666664e-06"/>
    </inertial>
    <collision>
      <origin rpy="3.14159265359 0 0" xyz="-0.08549999999999999 0.007 0.01025"/>
      <geometry>
        <mesh filename="/home/parallels/catkin_ws/src/grasp_refinement/reflex_stack/reflex_simulator/description/meshes/reflex/distal_coll.stl"/>
      </geometry>
    </collision>
  </link>
  <joint name="distal_1_to_pad" type="fixed">
    <origin rpy="1.570796326795 0 -1.570796326795" xyz="0 0 0"/>
    <parent link="distal_1"/>
    <child link="distal_1_pad"/>
  </joint>
  <link name="distal_1_pad">
    <visual>
      <!-- setting these xyz values by eye as transformations get too complex -->
      <origin rpy="1.570796326795 1.570796326795 0" xyz="-0.008 0.0155 0.076"/>
      <geometry>
        <mesh filename="/home/parallels/catkin_ws/src/grasp_refinement/reflex_stack/reflex_simulator/description/meshes/reflex/distal_pad.stl"/>
      </geometry>
      <material name="dark_grey"/>
    </visual>
    <inertial>
      <origin rpy="0 0 0" xyz="0 0.006999999999999999 -0.01875"/>
      <mass value="0.01"/>
      <inertia ixx="1.5052083333333334e-06" ixy="0.0" ixz="0.0" iyy="1.4485416666666665e-06" iyz="0.0" izz="4.833333333333333e-07"/>
    </inertial>
    <collision>
      <origin rpy="1.570796326795 1.570796326795 0" xyz="-0.008 0.0155 0.076"/>
      <geometry>
        <mesh filename="/home/parallels/catkin_ws/src/grasp_refinement/reflex_stack/reflex_simulator/description/meshes/reflex/distal_pad_coll.stl"/>
      </geometry>
    </collision>
  </link>
  <joint name="preshape_2" type="revolute">
    <parent link="shell"/>
    <child link="swivel_2"/>
    <dynamics damping="0.1" friction="0.0"/>
    <limit effort="2" lower="0.0" upper="1.570796326795" velocity="0.5"/>
    <origin rpy="0 0 0" xyz="0.0503973683071413 0.026 0.063"/>
    <axis xyz="0 0 1"/>
  </joint>
  <link name="swivel_2">
    <visual>
      <origin rpy="0 0 0" xyz="0 0 0"/>
      <geometry>
        <mesh filename="/home/parallels/catkin_ws/src/grasp_refinement/reflex_stack/reflex_simulator/description/meshes/reflex/swivel_2.stl"/>
      </geometry>
      <material name="black"/>
    </visual>
    <inertial>
      <origin rpy="0 0 0" xyz="0 0 0.0075"/>
      <mass value="0.02"/>
      <inertia ixx="1.8749999999999998e-06" ixy="0.0" ixz="0.0" iyy="1.8749999999999998e-06" iyz="0.0" izz="2.9999999999999997e-06"/>
    </inertial>
    <collision>
      <origin rpy="0 0 0" xyz="0 0 0"/>
      <geometry>
        <mesh filename="/home/parallels/catkin_ws/src/grasp_refinement/reflex_stack/reflex_simulator/description/meshes/reflex/swivel_2_coll.stl"/>
      </geometry>
    </collision>
  </link>
  <joint name="proximal_joint_2" type="revolute">
    <child link="proximal_2"/>
    <axis xyz="0 -1 0"/>
    <dynamics damping="0.1" friction="0.0"/>
    <limit effort="2" lower="0.0" upper="3.14159265359" velocity="0.5"/>
    <origin rpy="0 0.28 0" xyz="0.01 0 0.0186"/>
    <parent link="swivel_2"/>
  </joint>
  <link name="proximal_2">
    <visual>
      <origin rpy="3.14159265359 0 0" xyz="-0.011 0.007 0.011"/>
      <geometry>
        <mesh filename="/home/parallels/catkin_ws/src/grasp_refinement/reflex_stack/reflex_simulator/description/meshes/reflex/proximal.stl"/>
      </geometry>
      <material name="black"/>
    </visual>
    <inertial>
      <origin rpy="0 0 0" xyz="0.024499999999999997 0 0"/>
      <mass value="0.025"/>
      <inertia ixx="7.083333333333334e-07" ixy="0.0" ixz="0.0" iyy="1.0802083333333333e-05" iyz="0.0" izz="1.0910416666666665e-05"/>
    </inertial>
    <collision>
      <origin rpy="3.14159265359 0 0" xyz="-0.011 0.007 0.011"/>
      <geometry>
        <mesh filename="/home/parallels/catkin_ws/src/grasp_refinement/reflex_stack/reflex_simulator/description/meshes/reflex/proximal_coll.stl"/>
      </geometry>
    </collision>
  </link>
  <joint name="proximal_2_to_pad" type="fixed">
    <origin rpy="1.570796326795 0 -1.570796326795" xyz="0 0 0"/>
    <parent link="proximal_2"/>
    <child link="proximal_2_pad"/>
  </joint>
  <link name="proximal_2_pad">
    <visual>
      <origin rpy="1.570796326795 1.570796326795 0" xyz="-0.008 0.014 -0.002"/>
      <geometry>
        <mesh filename="/home/parallels/catkin_ws/src/grasp_refinement/reflex_stack/reflex_simulator/description/meshes/reflex/proximal_pad.stl"/>
      </geometry>
      <material name="dark_grey"/>
    </visual>
    <inertial>
      <origin rpy="0 0 0" xyz="0 0.004 -0.036"/>
      <mass value="0.015"/>
      <inertia ixx="3.879999999999999e-06" ixy="0.0" ixz="0.0" iyy="3.6999999999999993e-06" iyz="0.0" izz="8.199999999999999e-07"/>
    </inertial>
    <collision>
      <origin rpy="1.570796326795 1.570796326795 0" xyz="-0.008 0.014 -0.002"/>
      <geometry>
        <mesh filename="/home/parallels/catkin_ws/src/grasp_refinement/reflex_stack/reflex_simulator/description/meshes/reflex/proximal_pad_coll.stl"/>
      </geometry>
    </collision>
  </link>
  <joint name="proximal_2_to_flex" type="revolute">
    <origin rpy="0 0 0" xyz="0.06199999999999999 0 -0.002"/>
    <parent link="proximal_2"/>
    <child link="finger_2_flex_link"/>
    <axis xyz="0 -1 0"/>
    <dynamics damping="0.05" friction="0.0"/>
    <limit effort="1.0" lower="0.0" upper="0.5235987755983333" velocity="0.25"/>
  </joint>
  <link name="finger_2_flex_link">
    <visual>
      <origin rpy="0 0 0" xyz="0.0085 0 0.00325"/>
      <geometry>
        <box size="0.017 0.014 0.0065"/>
      </geometry>
      <material name="gold"/>
    </visual>
    <inertial>
      <origin rpy="0 0 0" xyz="0.0085 0 0.00325"/>
      <mass value="0.02"/>
      <inertia ixx="3.970833333333333e-07" ixy="0.0" ixz="0.0" iyy="5.520833333333334e-07" iyz="0.0" izz="8.083333333333335e-07"/>
    </inertial>
    <collision>
      <origin rpy="0 0 0" xyz="0.0085 0 0.00325"/>
      <geometry>
        <box size="0.017 0.014 0.0065"/>
      </geometry>
    </collision>
  </link>
  <joint name="flex_to_distal_2" type="revolute">
    <origin rpy="0 0 0" xyz="0.017 0 0"/>
    <parent link="finger_2_flex_link"/>
    <child link="distal_2"/>
    <axis xyz="0 -1 0"/>
    <dynamics damping="0.05" friction="0.0"/>
    <limit effort="1.0" lower="0.0" upper="0.5235987755983333" velocity="0.25"/>
  </joint>
  <link name="distal_2">
    <visual>
      <origin rpy="3.14159265359 0 0" xyz="-0.08549999999999999 0.007 0.01225"/>
      <geometry>
        <mesh filename="/home/parallels/catkin_ws/src/grasp_refinement/reflex_stack/reflex_simulator/description/meshes/reflex/distal.stl"/>
      </geometry>
      <material name="black"/>
    </visual>
    <inertial>
      <origin rpy="0 0 0" xyz="0.018 0 0.004"/>
      <mass value="0.02"/>
      <inertia ixx="5.666666666666667e-07" ixy="0.0" ixz="0.0" iyy="2.3999999999999995e-06" iyz="0.0" izz="2.4866666666666664e-06"/>
    </inertial>
    <collision>
      <origin rpy="3.14159265359 0 0" xyz="-0.08549999999999999 0.007 0.01025"/>
      <geometry>
        <mesh filename="/home/parallels/catkin_ws/src/grasp_refinement/reflex_stack/reflex_simulator/description/meshes/reflex/distal_coll.stl"/>
      </geometry>
    </collision>
  </link>
  <joint name="distal_2_to_pad" type="fixed">
    <origin rpy="1.570796326795 0 -1.570796326795" xyz="0 0 0"/>
    <parent link="distal_2"/>
    <child link="distal_2_pad"/>
  </joint>
  <link name="distal_2_pad">
    <visual>
      <!-- setting these xyz values by eye as transformations get too complex -->
      <origin rpy="1.570796326795 1.570796326795 0" xyz="-0.008 0.0155 0.076"/>
      <geometry>
        <mesh filename="/home/parallels/catkin_ws/src/grasp_refinement/reflex_stack/reflex_simulator/description/meshes/reflex/distal_pad.stl"/>
      </geometry>
      <material name="dark_grey"/>
    </visual>
    <inertial>
      <origin rpy="0 0 0" xyz="0 0.006999999999999999 -0.01875"/>
      <mass value="0.01"/>
      <inertia ixx="1.5052083333333334e-06" ixy="0.0" ixz="0.0" iyy="1.4485416666666665e-06" iyz="0.0" izz="4.833333333333333e-07"/>
    </inertial>
    <collision>
      <origin rpy="1.570796326795 1.570796326795 0" xyz="-0.008 0.0155 0.076"/>
      <geometry>
        <mesh filename="/home/parallels/catkin_ws/src/grasp_refinement/reflex_stack/reflex_simulator/description/meshes/reflex/distal_pad_coll.stl"/>
      </geometry>
    </collision>
  </link>
  <joint name="proximal_joint_3" type="revolute">
    <child link="proximal_3"/>
    <axis xyz="0 -1 0"/>
    <dynamics damping="0.1" friction="0.0"/>
    <limit effort="2" lower="0.0" upper="3.14159265359" velocity="0.5"/>
    <origin rpy="0 0.28 3.14159265359" xyz="-0.03 0 0.0816"/>
    <parent link="shell"/>
  </joint>
  <link name="proximal_3">
    <visual>
      <origin rpy="3.14159265359 0 0" xyz="-0.011 0.007 0.011"/>
      <geometry>
        <mesh filename="/home/parallels/catkin_ws/src/grasp_refinement/reflex_stack/reflex_simulator/description/meshes/reflex/proximal.stl"/>
      </geometry>
      <material name="black"/>
    </visual>
    <inertial>
      <origin rpy="0 0 0" xyz="0.024499999999999997 0 0"/>
      <mass value="0.025"/>
      <inertia ixx="7.083333333333334e-07" ixy="0.0" ixz="0.0" iyy="1.0802083333333333e-05" iyz="0.0" izz="1.0910416666666665e-05"/>
    </inertial>
    <collision>
      <origin rpy="3.14159265359 0 0" xyz="-0.011 0.007 0.011"/>
      <geometry>
        <mesh filename="/home/parallels/catkin_ws/src/grasp_refinement/reflex_stack/reflex_simulator/description/meshes/reflex/proximal_coll.stl"/>
      </geometry>
    </collision>
  </link>
  <joint name="proximal_3_to_pad" type="fixed">
    <origin rpy="1.570796326795 0 -1.570796326795" xyz="0 0 0"/>
    <parent link="proximal_3"/>
    <child link="proximal_3_pad"/>
  </joint>
  <link name="proximal_3_pad">
    <visual>
      <origin rpy="1.570796326795 1.570796326795 0" xyz="-0.008 0.014 -0.002"/>
      <geometry>
        <mesh filename="/home/parallels/catkin_ws/src/grasp_refinement/reflex_stack/reflex_simulator/description/meshes/reflex/proximal_pad.stl"/>
      </geometry>
      <material name="dark_grey"/>
    </visual>
    <inertial>
      <origin rpy="0 0 0" xyz="0 0.004 -0.036"/>
      <mass value="0.015"/>
      <inertia ixx="3.879999999999999e-06" ixy="0.0" ixz="0.0" iyy="3.6999999999999993e-06" iyz="0.0" izz="8.199999999999999e-07"/>
    </inertial>
    <collision>
      <origin rpy="1.570796326795 1.570796326795 0" xyz="-0.008 0.014 -0.002"/>
      <geometry>
        <mesh filename="/home/parallels/catkin_ws/src/grasp_refinement/reflex_stack/reflex_simulator/description/meshes/reflex/proximal_pad_coll.stl"/>
      </geometry>
    </collision>
  </link>
  <joint name="proximal_3_to_flex" type="revolute">
    <origin rpy="0 0 0" xyz="0.06199999999999999 0 -0.002"/>
    <parent link="proximal_3"/>
    <child link="finger_3_flex_link"/>
    <axis xyz="0 -1 0"/>
    <dynamics damping="0.05" friction="0.0"/>
    <limit effort="1.0" lower="0.0" upper="0.5235987755983333" velocity="0.25"/>
  </joint>
  <link name="finger_3_flex_link">
    <visual>
      <origin rpy="0 0 0" xyz="0.0085 0 0.00325"/>
      <geometry>
        <box size="0.017 0.014 0.0065"/>
      </geometry>
      <material name="gold"/>
    </visual>
    <inertial>
      <origin rpy="0 0 0" xyz="0.0085 0 0.00325"/>
      <mass value="0.02"/>
      <inertia ixx="3.970833333333333e-07" ixy="0.0" ixz="0.0" iyy="5.520833333333334e-07" iyz="0.0" izz="8.083333333333335e-07"/>
    </inertial>
    <collision>
      <origin rpy="0 0 0" xyz="0.0085 0 0.00325"/>
      <geometry>
        <box size="0.017 0.014 0.0065"/>
      </geometry>
    </collision>
  </link>
  <joint name="flex_to_distal_3" type="revolute">
    <origin rpy="0 0 0" xyz="0.017 0 0"/>
    <parent link="finger_3_flex_link"/>
    <child link="distal_3"/>
    <axis xyz="0 -1 0"/>
    <dynamics damping="0.05" friction="0.0"/>
    <limit effort="1.0" lower="0.0" upper="0.5235987755983333" velocity="0.25"/>
  </joint>
  <link name="distal_3">
    <visual>
      <origin rpy="3.14159265359 0 0" xyz="-0.08549999999999999 0.007 0.01225"/>
      <geometry>
        <mesh filename="/home/parallels/catkin_ws/src/grasp_refinement/reflex_stack/reflex_simulator/description/meshes/reflex/distal.stl"/>
      </geometry>
      <material name="black"/>
    </visual>
    <inertial>
      <origin rpy="0 0 0" xyz="0.018 0 0.004"/>
      <mass value="0.02"/>
      <inertia ixx="5.666666666666667e-07" ixy="0.0" ixz="0.0" iyy="2.3999999999999995e-06" iyz="0.0" izz="2.4866666666666664e-06"/>
    </inertial>
    <collision>
      <origin rpy="3.14159265359 0 0" xyz="-0.08549999999999999 0.007 0.01025"/>
      <geometry>
        <mesh filename="/home/parallels/catkin_ws/src/grasp_refinement/reflex_stack/reflex_simulator/description/meshes/reflex/distal_coll.stl"/>
      </geometry>
    </collision>
  </link>
  <joint name="distal_3_to_pad" type="fixed">
    <origin rpy="1.570796326795 0 -1.570796326795" xyz="0 0 0"/>
    <parent link="distal_3"/>
    <child link="distal_3_pad"/>
  </joint>
  <link name="distal_3_pad">
    <visual>
      <!-- setting these xyz values by eye as transformations get too complex -->
      <origin rpy="1.570796326795 1.570796326795 0" xyz="-0.008 0.0155 0.076"/>
      <geometry>
        <mesh filename="/home/parallels/catkin_ws/src/grasp_refinement/reflex_stack/reflex_simulator/description/meshes/reflex/distal_pad.stl"/>
      </geometry>
      <material name="dark_grey"/>
    </visual>
    <inertial>
      <origin rpy="0 0 0" xyz="0 0.006999999999999999 -0.01875"/>
      <mass value="0.01"/>
      <inertia ixx="1.5052083333333334e-06" ixy="0.0" ixz="0.0" iyy="1.4485416666666665e-06" iyz="0.0" izz="4.833333333333333e-07"/>
    </inertial>
    <collision>
      <origin rpy="1.570796326795 1.570796326795 0" xyz="-0.008 0.0155 0.076"/>
      <geometry>
        <mesh filename="/home/parallels/catkin_ws/src/grasp_refinement/reflex_stack/reflex_simulator/description/meshes/reflex/distal_pad_coll.stl"/>
      </geometry>
    </collision>
  </link>
</robot>

